2023-02-12 02:52:56 ERROR 500 response executing GraphQL.
2023-02-12 02:52:56 ERROR {"errors":[{"message":"An internal error occurred. Please contact support.","path":["upsertSweep"]}],"data":{"upsertSweep":null}}
2023-02-14 04:10:15 ERROR 400 response executing GraphQL.
2023-02-14 04:10:15 ERROR {"errors":[{"message":"Invalid configuration for hyperparameter 'cfg'","path":["upsertSweep"]}],"data":{"upsertSweep":null}}
2023-02-14 04:10:15 ERROR Traceback (most recent call last):
  File "/opt/conda/lib/python3.9/site-packages/wandb/sdk/lib/retry.py", line 113, in __call__
    result = self._call_fn(*args, **kwargs)
  File "/opt/conda/lib/python3.9/site-packages/wandb/sdk/internal/internal_api.py", line 210, in execute
    return self.client.execute(*args, **kwargs)  # type: ignore
  File "/opt/conda/lib/python3.9/site-packages/wandb/vendor/gql-0.2.0/wandb_gql/client.py", line 52, in execute
    result = self._get_result(document, *args, **kwargs)
  File "/opt/conda/lib/python3.9/site-packages/wandb/vendor/gql-0.2.0/wandb_gql/client.py", line 60, in _get_result
    return self.transport.execute(document, *args, **kwargs)
  File "/opt/conda/lib/python3.9/site-packages/wandb/vendor/gql-0.2.0/wandb_gql/transport/requests.py", line 39, in execute
    request.raise_for_status()
  File "/opt/conda/lib/python3.9/site-packages/requests/models.py", line 1021, in raise_for_status
    raise HTTPError(http_error_msg, response=self)
requests.exceptions.HTTPError: 400 Client Error: Bad Request for url: https://api.wandb.ai/graphql

During handling of the above exception, another exception occurred:

Traceback (most recent call last):
  File "/opt/conda/lib/python3.9/site-packages/wandb/apis/normalize.py", line 26, in wrapper
    return func(*args, **kwargs)
  File "/opt/conda/lib/python3.9/site-packages/wandb/sdk/internal/internal_api.py", line 2220, in upsert_sweep
    raise e
  File "/opt/conda/lib/python3.9/site-packages/wandb/sdk/internal/internal_api.py", line 2205, in upsert_sweep
    response = self.gql(
  File "/opt/conda/lib/python3.9/site-packages/wandb/sdk/lib/retry.py", line 129, in __call__
    retry_timedelta_triggered = check_retry_fn(e)
  File "/opt/conda/lib/python3.9/site-packages/wandb/util.py", line 974, in no_retry_4xx
    raise UsageError(body["errors"][0]["message"])
wandb.errors.UsageError: Invalid configuration for hyperparameter 'cfg'

During handling of the above exception, another exception occurred:

Traceback (most recent call last):
  File "/opt/conda/lib/python3.9/site-packages/wandb/cli/cli.py", line 97, in wrapper
    return func(*args, **kwargs)
  File "/opt/conda/lib/python3.9/site-packages/wandb/cli/cli.py", line 933, in sweep
    sweep_id, warnings = api.upsert_sweep(
  File "/opt/conda/lib/python3.9/site-packages/wandb/apis/internal.py", line 102, in upsert_sweep
    return self.api.upsert_sweep(*args, **kwargs)
  File "/opt/conda/lib/python3.9/site-packages/wandb/apis/normalize.py", line 62, in wrapper
    raise CommError(message, err).with_traceback(sys.exc_info()[2])
  File "/opt/conda/lib/python3.9/site-packages/wandb/apis/normalize.py", line 26, in wrapper
    return func(*args, **kwargs)
  File "/opt/conda/lib/python3.9/site-packages/wandb/sdk/internal/internal_api.py", line 2220, in upsert_sweep
    raise e
  File "/opt/conda/lib/python3.9/site-packages/wandb/sdk/internal/internal_api.py", line 2205, in upsert_sweep
    response = self.gql(
  File "/opt/conda/lib/python3.9/site-packages/wandb/sdk/lib/retry.py", line 129, in __call__
    retry_timedelta_triggered = check_retry_fn(e)
  File "/opt/conda/lib/python3.9/site-packages/wandb/util.py", line 974, in no_retry_4xx
    raise UsageError(body["errors"][0]["message"])
wandb.errors.CommError: Invalid configuration for hyperparameter 'cfg'

2023-02-14 04:10:29 ERROR 400 response executing GraphQL.
2023-02-14 04:10:29 ERROR {"errors":[{"message":"Invalid configuration for hyperparameter 'cfg'","path":["upsertSweep"]}],"data":{"upsertSweep":null}}
2023-02-14 04:10:29 ERROR Traceback (most recent call last):
  File "/opt/conda/lib/python3.9/site-packages/wandb/sdk/lib/retry.py", line 113, in __call__
    result = self._call_fn(*args, **kwargs)
  File "/opt/conda/lib/python3.9/site-packages/wandb/sdk/internal/internal_api.py", line 210, in execute
    return self.client.execute(*args, **kwargs)  # type: ignore
  File "/opt/conda/lib/python3.9/site-packages/wandb/vendor/gql-0.2.0/wandb_gql/client.py", line 52, in execute
    result = self._get_result(document, *args, **kwargs)
  File "/opt/conda/lib/python3.9/site-packages/wandb/vendor/gql-0.2.0/wandb_gql/client.py", line 60, in _get_result
    return self.transport.execute(document, *args, **kwargs)
  File "/opt/conda/lib/python3.9/site-packages/wandb/vendor/gql-0.2.0/wandb_gql/transport/requests.py", line 39, in execute
    request.raise_for_status()
  File "/opt/conda/lib/python3.9/site-packages/requests/models.py", line 1021, in raise_for_status
    raise HTTPError(http_error_msg, response=self)
requests.exceptions.HTTPError: 400 Client Error: Bad Request for url: https://api.wandb.ai/graphql

During handling of the above exception, another exception occurred:

Traceback (most recent call last):
  File "/opt/conda/lib/python3.9/site-packages/wandb/apis/normalize.py", line 26, in wrapper
    return func(*args, **kwargs)
  File "/opt/conda/lib/python3.9/site-packages/wandb/sdk/internal/internal_api.py", line 2220, in upsert_sweep
    raise e
  File "/opt/conda/lib/python3.9/site-packages/wandb/sdk/internal/internal_api.py", line 2205, in upsert_sweep
    response = self.gql(
  File "/opt/conda/lib/python3.9/site-packages/wandb/sdk/lib/retry.py", line 129, in __call__
    retry_timedelta_triggered = check_retry_fn(e)
  File "/opt/conda/lib/python3.9/site-packages/wandb/util.py", line 974, in no_retry_4xx
    raise UsageError(body["errors"][0]["message"])
wandb.errors.UsageError: Invalid configuration for hyperparameter 'cfg'

During handling of the above exception, another exception occurred:

Traceback (most recent call last):
  File "/opt/conda/lib/python3.9/site-packages/wandb/cli/cli.py", line 97, in wrapper
    return func(*args, **kwargs)
  File "/opt/conda/lib/python3.9/site-packages/wandb/cli/cli.py", line 933, in sweep
    sweep_id, warnings = api.upsert_sweep(
  File "/opt/conda/lib/python3.9/site-packages/wandb/apis/internal.py", line 102, in upsert_sweep
    return self.api.upsert_sweep(*args, **kwargs)
  File "/opt/conda/lib/python3.9/site-packages/wandb/apis/normalize.py", line 62, in wrapper
    raise CommError(message, err).with_traceback(sys.exc_info()[2])
  File "/opt/conda/lib/python3.9/site-packages/wandb/apis/normalize.py", line 26, in wrapper
    return func(*args, **kwargs)
  File "/opt/conda/lib/python3.9/site-packages/wandb/sdk/internal/internal_api.py", line 2220, in upsert_sweep
    raise e
  File "/opt/conda/lib/python3.9/site-packages/wandb/sdk/internal/internal_api.py", line 2205, in upsert_sweep
    response = self.gql(
  File "/opt/conda/lib/python3.9/site-packages/wandb/sdk/lib/retry.py", line 129, in __call__
    retry_timedelta_triggered = check_retry_fn(e)
  File "/opt/conda/lib/python3.9/site-packages/wandb/util.py", line 974, in no_retry_4xx
    raise UsageError(body["errors"][0]["message"])
wandb.errors.CommError: Invalid configuration for hyperparameter 'cfg'

2023-02-14 04:11:08 ERROR 400 response executing GraphQL.
2023-02-14 04:11:08 ERROR {"errors":[{"message":"Invalid sweep config: invalid hyperparameter configuration: cfg","path":["upsertSweep"]}],"data":{"upsertSweep":null}}
2023-02-14 04:11:08 ERROR Traceback (most recent call last):
  File "/opt/conda/lib/python3.9/site-packages/wandb/sdk/lib/retry.py", line 113, in __call__
    result = self._call_fn(*args, **kwargs)
  File "/opt/conda/lib/python3.9/site-packages/wandb/sdk/internal/internal_api.py", line 210, in execute
    return self.client.execute(*args, **kwargs)  # type: ignore
  File "/opt/conda/lib/python3.9/site-packages/wandb/vendor/gql-0.2.0/wandb_gql/client.py", line 52, in execute
    result = self._get_result(document, *args, **kwargs)
  File "/opt/conda/lib/python3.9/site-packages/wandb/vendor/gql-0.2.0/wandb_gql/client.py", line 60, in _get_result
    return self.transport.execute(document, *args, **kwargs)
  File "/opt/conda/lib/python3.9/site-packages/wandb/vendor/gql-0.2.0/wandb_gql/transport/requests.py", line 39, in execute
    request.raise_for_status()
  File "/opt/conda/lib/python3.9/site-packages/requests/models.py", line 1021, in raise_for_status
    raise HTTPError(http_error_msg, response=self)
requests.exceptions.HTTPError: 400 Client Error: Bad Request for url: https://api.wandb.ai/graphql

During handling of the above exception, another exception occurred:

Traceback (most recent call last):
  File "/opt/conda/lib/python3.9/site-packages/wandb/apis/normalize.py", line 26, in wrapper
    return func(*args, **kwargs)
  File "/opt/conda/lib/python3.9/site-packages/wandb/sdk/internal/internal_api.py", line 2220, in upsert_sweep
    raise e
  File "/opt/conda/lib/python3.9/site-packages/wandb/sdk/internal/internal_api.py", line 2205, in upsert_sweep
    response = self.gql(
  File "/opt/conda/lib/python3.9/site-packages/wandb/sdk/lib/retry.py", line 129, in __call__
    retry_timedelta_triggered = check_retry_fn(e)
  File "/opt/conda/lib/python3.9/site-packages/wandb/util.py", line 974, in no_retry_4xx
    raise UsageError(body["errors"][0]["message"])
wandb.errors.UsageError: Invalid sweep config: invalid hyperparameter configuration: cfg

During handling of the above exception, another exception occurred:

Traceback (most recent call last):
  File "/opt/conda/lib/python3.9/site-packages/wandb/cli/cli.py", line 97, in wrapper
    return func(*args, **kwargs)
  File "/opt/conda/lib/python3.9/site-packages/wandb/cli/cli.py", line 933, in sweep
    sweep_id, warnings = api.upsert_sweep(
  File "/opt/conda/lib/python3.9/site-packages/wandb/apis/internal.py", line 102, in upsert_sweep
    return self.api.upsert_sweep(*args, **kwargs)
  File "/opt/conda/lib/python3.9/site-packages/wandb/apis/normalize.py", line 62, in wrapper
    raise CommError(message, err).with_traceback(sys.exc_info()[2])
  File "/opt/conda/lib/python3.9/site-packages/wandb/apis/normalize.py", line 26, in wrapper
    return func(*args, **kwargs)
  File "/opt/conda/lib/python3.9/site-packages/wandb/sdk/internal/internal_api.py", line 2220, in upsert_sweep
    raise e
  File "/opt/conda/lib/python3.9/site-packages/wandb/sdk/internal/internal_api.py", line 2205, in upsert_sweep
    response = self.gql(
  File "/opt/conda/lib/python3.9/site-packages/wandb/sdk/lib/retry.py", line 129, in __call__
    retry_timedelta_triggered = check_retry_fn(e)
  File "/opt/conda/lib/python3.9/site-packages/wandb/util.py", line 974, in no_retry_4xx
    raise UsageError(body["errors"][0]["message"])
wandb.errors.CommError: Invalid sweep config: invalid hyperparameter configuration: cfg

2023-02-14 04:11:20 ERROR 400 response executing GraphQL.
2023-02-14 04:11:20 ERROR {"errors":[{"message":"Invalid sweep config: invalid hyperparameter configuration: cfg","path":["upsertSweep"]}],"data":{"upsertSweep":null}}
2023-02-14 04:11:20 ERROR Traceback (most recent call last):
  File "/opt/conda/lib/python3.9/site-packages/wandb/sdk/lib/retry.py", line 113, in __call__
    result = self._call_fn(*args, **kwargs)
  File "/opt/conda/lib/python3.9/site-packages/wandb/sdk/internal/internal_api.py", line 210, in execute
    return self.client.execute(*args, **kwargs)  # type: ignore
  File "/opt/conda/lib/python3.9/site-packages/wandb/vendor/gql-0.2.0/wandb_gql/client.py", line 52, in execute
    result = self._get_result(document, *args, **kwargs)
  File "/opt/conda/lib/python3.9/site-packages/wandb/vendor/gql-0.2.0/wandb_gql/client.py", line 60, in _get_result
    return self.transport.execute(document, *args, **kwargs)
  File "/opt/conda/lib/python3.9/site-packages/wandb/vendor/gql-0.2.0/wandb_gql/transport/requests.py", line 39, in execute
    request.raise_for_status()
  File "/opt/conda/lib/python3.9/site-packages/requests/models.py", line 1021, in raise_for_status
    raise HTTPError(http_error_msg, response=self)
requests.exceptions.HTTPError: 400 Client Error: Bad Request for url: https://api.wandb.ai/graphql

During handling of the above exception, another exception occurred:

Traceback (most recent call last):
  File "/opt/conda/lib/python3.9/site-packages/wandb/apis/normalize.py", line 26, in wrapper
    return func(*args, **kwargs)
  File "/opt/conda/lib/python3.9/site-packages/wandb/sdk/internal/internal_api.py", line 2220, in upsert_sweep
    raise e
  File "/opt/conda/lib/python3.9/site-packages/wandb/sdk/internal/internal_api.py", line 2205, in upsert_sweep
    response = self.gql(
  File "/opt/conda/lib/python3.9/site-packages/wandb/sdk/lib/retry.py", line 129, in __call__
    retry_timedelta_triggered = check_retry_fn(e)
  File "/opt/conda/lib/python3.9/site-packages/wandb/util.py", line 974, in no_retry_4xx
    raise UsageError(body["errors"][0]["message"])
wandb.errors.UsageError: Invalid sweep config: invalid hyperparameter configuration: cfg

During handling of the above exception, another exception occurred:

Traceback (most recent call last):
  File "/opt/conda/lib/python3.9/site-packages/wandb/cli/cli.py", line 97, in wrapper
    return func(*args, **kwargs)
  File "/opt/conda/lib/python3.9/site-packages/wandb/cli/cli.py", line 933, in sweep
    sweep_id, warnings = api.upsert_sweep(
  File "/opt/conda/lib/python3.9/site-packages/wandb/apis/internal.py", line 102, in upsert_sweep
    return self.api.upsert_sweep(*args, **kwargs)
  File "/opt/conda/lib/python3.9/site-packages/wandb/apis/normalize.py", line 62, in wrapper
    raise CommError(message, err).with_traceback(sys.exc_info()[2])
  File "/opt/conda/lib/python3.9/site-packages/wandb/apis/normalize.py", line 26, in wrapper
    return func(*args, **kwargs)
  File "/opt/conda/lib/python3.9/site-packages/wandb/sdk/internal/internal_api.py", line 2220, in upsert_sweep
    raise e
  File "/opt/conda/lib/python3.9/site-packages/wandb/sdk/internal/internal_api.py", line 2205, in upsert_sweep
    response = self.gql(
  File "/opt/conda/lib/python3.9/site-packages/wandb/sdk/lib/retry.py", line 129, in __call__
    retry_timedelta_triggered = check_retry_fn(e)
  File "/opt/conda/lib/python3.9/site-packages/wandb/util.py", line 974, in no_retry_4xx
    raise UsageError(body["errors"][0]["message"])
wandb.errors.CommError: Invalid sweep config: invalid hyperparameter configuration: cfg

2023-02-22 21:47:52 ERROR 400 response executing GraphQL.
2023-02-22 21:47:52 ERROR {"errors":[{"message":"Invalid sweep config: invalid hyperparameter configuration: augm","path":["upsertSweep"]}],"data":{"upsertSweep":null}}
2023-02-22 21:47:52 ERROR Traceback (most recent call last):
  File "/data/kpusteln/my-envs/swin/lib/python3.7/site-packages/wandb/sdk/lib/retry.py", line 113, in __call__
    result = self._call_fn(*args, **kwargs)
  File "/data/kpusteln/my-envs/swin/lib/python3.7/site-packages/wandb/sdk/internal/internal_api.py", line 209, in execute
    return self.client.execute(*args, **kwargs)  # type: ignore
  File "/data/kpusteln/my-envs/swin/lib/python3.7/site-packages/wandb/vendor/gql-0.2.0/wandb_gql/client.py", line 52, in execute
    result = self._get_result(document, *args, **kwargs)
  File "/data/kpusteln/my-envs/swin/lib/python3.7/site-packages/wandb/vendor/gql-0.2.0/wandb_gql/client.py", line 60, in _get_result
    return self.transport.execute(document, *args, **kwargs)
  File "/data/kpusteln/my-envs/swin/lib/python3.7/site-packages/wandb/vendor/gql-0.2.0/wandb_gql/transport/requests.py", line 39, in execute
    request.raise_for_status()
  File "/data/kpusteln/my-envs/swin/lib/python3.7/site-packages/requests/models.py", line 1021, in raise_for_status
    raise HTTPError(http_error_msg, response=self)
requests.exceptions.HTTPError: 400 Client Error: Bad Request for url: https://api.wandb.ai/graphql

During handling of the above exception, another exception occurred:

Traceback (most recent call last):
  File "/data/kpusteln/my-envs/swin/lib/python3.7/site-packages/wandb/apis/normalize.py", line 26, in wrapper
    return func(*args, **kwargs)
  File "/data/kpusteln/my-envs/swin/lib/python3.7/site-packages/wandb/sdk/internal/internal_api.py", line 2218, in upsert_sweep
    raise e
  File "/data/kpusteln/my-envs/swin/lib/python3.7/site-packages/wandb/sdk/internal/internal_api.py", line 2215, in upsert_sweep
    check_retry_fn=util.no_retry_4xx,
  File "/data/kpusteln/my-envs/swin/lib/python3.7/site-packages/wandb/sdk/lib/retry.py", line 129, in __call__
    retry_timedelta_triggered = check_retry_fn(e)
  File "/data/kpusteln/my-envs/swin/lib/python3.7/site-packages/wandb/util.py", line 969, in no_retry_4xx
    raise UsageError(body["errors"][0]["message"])
wandb.errors.UsageError: Invalid sweep config: invalid hyperparameter configuration: augm

During handling of the above exception, another exception occurred:

Traceback (most recent call last):
  File "/data/kpusteln/my-envs/swin/lib/python3.7/site-packages/wandb/cli/cli.py", line 97, in wrapper
    return func(*args, **kwargs)
  File "/data/kpusteln/my-envs/swin/lib/python3.7/site-packages/wandb/cli/cli.py", line 941, in sweep
    launch_scheduler=_launch_scheduler_spec,
  File "/data/kpusteln/my-envs/swin/lib/python3.7/site-packages/wandb/apis/internal.py", line 102, in upsert_sweep
    return self.api.upsert_sweep(*args, **kwargs)
  File "/data/kpusteln/my-envs/swin/lib/python3.7/site-packages/wandb/apis/normalize.py", line 62, in wrapper
    raise CommError(message, err).with_traceback(sys.exc_info()[2])
  File "/data/kpusteln/my-envs/swin/lib/python3.7/site-packages/wandb/apis/normalize.py", line 26, in wrapper
    return func(*args, **kwargs)
  File "/data/kpusteln/my-envs/swin/lib/python3.7/site-packages/wandb/sdk/internal/internal_api.py", line 2218, in upsert_sweep
    raise e
  File "/data/kpusteln/my-envs/swin/lib/python3.7/site-packages/wandb/sdk/internal/internal_api.py", line 2215, in upsert_sweep
    check_retry_fn=util.no_retry_4xx,
  File "/data/kpusteln/my-envs/swin/lib/python3.7/site-packages/wandb/sdk/lib/retry.py", line 129, in __call__
    retry_timedelta_triggered = check_retry_fn(e)
  File "/data/kpusteln/my-envs/swin/lib/python3.7/site-packages/wandb/util.py", line 969, in no_retry_4xx
    raise UsageError(body["errors"][0]["message"])
wandb.errors.CommError: Invalid sweep config: invalid hyperparameter configuration: augm

